sample_data.csv
type,timestamp,price,qty,side,trade_id
trade,1000000000,100.25,500,buy,T001
trade,1000000100,100.30,200,sell,T002
quote,1000000200,100.20,100.35,1000,1500
order,1000000300,12345,buy,100,100.15,limit
trade,1000000400,100.15,100,sell,T003
cancel,1000000500,12345,User requested
status,1000000600,open,Market opened
bbo,1000000700,100.10,100.40,800,1200
order,1000000800,12346,sell,200,,market
trade,1000000900,100.25,200,buy,T004
